Workbook

Sheet Planilla Global  - Cumplim (%)
D2: Lista de Verificación de Cumplimiento Requisitos Legales y Otros Aplicable a Seguridad, Salud Ocupacional, Medioambiente y Comunidad Contrato 4600029025 - SKIC CC-101 | H2: Código | I2: MTRSE-00002
H3: Revisión | I3: 3
H4: Fecha | I4: 46288
B6: N° | C6: Cuerpo Legal | D6: Organismo | E6: Materia | F6: Nombre del Cuerpo Legal | G6: % Cumplimiento | H6: Link | I6: Columna1
B7: 1 | C7: Ley 16.744 | D7: MINISTERIO DEL TRABAJO Y PREVISION SOCIAL. | E7: Seguridad y Salud | F7: Establece Normas sobre Accidentes del Trabajo y Enfermedades Profesionales | G7: 1 | H7: https://www.leychile.cl/Navegar?idNorma=28650&idVersion=2019-01-01 | I7: Vigente / Modificado
B8: 2 | C8: Ley 18.290 | D8: MINISTERIO DE JUSTICIA | E8: Seguridad | F8: Ley de Transito | G8: 1 | H8: https://www.leychile.cl/Navegar?idNorma=29708 | I8: Vigente
B9: 3 | C9: Ley 19.303 | D9: MINISTERIO DEL INTERIOR | E9: Seguridad | F9: Establece Obligaciones a Entidades que indica, en Materia de Seguridad de las Personas | G9: 1 | H9: https://www.leychile.cl/Navegar?idNorma=30670 | I9: Vigente
B10: 4 | C10: LEY 19.404 | D10: MINISTERIO DE SALUD | E10: RRHH | F10: Introduce modificación al Decreto Ley Nº 3.500, de 1980, Texto Original del 01-03-2009 y dicta normas relativas a pensiones de vejez, considerando el desempeño de trabajos pesados. | G10: N/A | H10: https://www.bcn.cl/leychile/navegar?idNorma=30771 | I10: Vigente
B11: 5 | C11: Ley 19.419 | D11: MINISTERIO DE SALUD | E11: Medio Ambiente | F11: Regula Actividades que indica Relacionadas con el Tabaco | G11: 1 | H11: https://www.leychile.cl/Navegar?idNorma=30786 | I11: Vigente / Modificado
B12: 6 | C12: Ley 19.518 | D12: MINISTERIO DEL TRABAJO Y PREVISIÓN | E12: RRHH | F12: Fija nuevo estatuto de capacitación y empleo | G12: 0 | H12: https://www.bcn.cl/leychile/navegar?idNorma=76201 | I12: Vigente
B13: 7 | C13: Ley 19.628 | D13: MINISTERIO SECRETARIA GENERAL DE LA PRESIDENCIA | E13: RRLL | F13: Derecho a la Privacidad | G13: 1 | H13: https://www.leychile.cl/Navegar?idNorma=141599 | I13: Vigente / Modificado
B14: 8 | C14: Ley 19.728 | D14: MINISTERIO DEL TRABAJO Y PREVISION SOCIAL. | E14: RRLL | F14: Establece un Seguro de desempleo | G14: 1 | H14: https://www.leychile.cl/Navegar?idNorma=184979 | I14: Vigente
B15: 9 | C15: LEY 20.000 | D15: MINISTERIO DEL INTERIOR | E15: RRHH | F15: Sustituye la ley Nº 19.366, que sanciona el trafico ilícito de estupefacientes y sustancias psicotrópicas | G15: 1 | H15: https://www.bcn.cl/leychile/navegar?idNorma=235507 | I15: Vigente
B16: 10 | C16: Ley 20.001 | D16: MINISTERIO DEL TRABAJO Y PREVISION SOCIAL. | E16: Seguridad | F16: Regula el Peso Máximo de Carga Humana | G16: 1 | H16: https://www.leychile.cl/Navegar?idNorma=235279 | I16: Modificada 20949
B17: 11 | C17: Ley 20.005 | D17: MINISTERIO DEL TRABAJO Y PREVISION SOCIAL. | E17: RRLL | F17: Tipifica y Sanciona el Acoso Sexual | G17: 1 | H17: https://www.leychile.cl/Navegar?idNorma=236425 | I17: Vigente / Modificado
B18: 12 | C18: Ley 20.047 | D18: MINISTERIO DEL TRABAJO Y PREVISION SOCIAL. | E18: RRLL | F18: Establece un Permiso Paternal en el Código del Trabajo | G18: 1 | H18: https://www.leychile.cl/Navegar?idNorma=241556 | I18: Vigente
B19: 13 | C19: LEY 20.068 | D19: MINISTERIO DE TRANSPORTE Y TELECOMUNICACIONES | E19: HSEC | F19: Actualización Ley de transito Introduce diversas modificaciones a la ley Nº 18.290, en materia de tránsito terrestre | G19: 1 | H19: https://www.bcn.cl/leychile/navegar?idNorma=244868 | I19: Vigente
B20: 14 | C20: Ley 20.096 | D20: MINISTERIO SECRETARIA GENERAL DE LA PRESIDENCIA | E20: Medio Ambiente | F20: Establece Mecanismos de Control Aplicables a la Sustancias Agotadoras de la Capa de Ozono | G20: 1 | H20: https://www.leychile.cl/Navegar?idNorma=248323 | I20: Vigente
B21: 15 | C21: Ley 20.101 | D21: MINISTERIO DEL TRABAJO Y PREVISION SOCIAL. | E21: Seguridad | F21: Amplia el concepto de accidente de Trabajo contemplado en la ley Nº 16.744, sobre Accidente del Trabajo y Enfermedades Profesionales | G21: 1 | H21: https://www.leychile.cl/Navegar?idNorma=249199 | I21: Vigente
B22: 16 | C22: LEY 20.105 | D22: Ministerio de Salud, Subsecretaria de Salud Pública | E22: RRLL | F22: Modifica la ley Nº 19.419, en materias relativas a la publicidad y el consumo del tabaco | G22: 1 | H22: https://www.bcn.cl/leychile/navegar?idNorma=249682&idVersion=2006-05-16 | I22: Vigente
... B71: 66 | C71: Decreto 48 | D71: MINISTERIO DEL TRABAJO Y PREVISIÓN SOCIAL | E71: Salud | F71: Introduce modificaciones en el reglamento para la aplicación de la ley N° 20.001 que regula el peso máximo de carga humana, contenido en el decreto supremo N°63 | G71: 1 | H71: Decreto-48 17-ENE-2018 MINISTERIO DEL TRABAJO Y PREVISIÓN SOCIAL - Ley Chile - Biblioteca del Congreso Nacional (bcn.cl) | I71: Vigente
B72: 67 | C72: Decreto 49 | D72: MINISTERIO DEL TRABAJO | E72: RRHH | F72: Modifica decreto supremo 71, de 1996, que aprueba reglamento para la aplicación de la ley 19.404, que introduce modificaciones al dl 3.500, y dicta normas relativas a pensiones de vejez | G72: N/A | H72: https://www.bcn.cl/leychile/navegar?i=1115974&f=2018-03-09&p=9893266 | I72: Vigente
B73: 68 | C73: Decreto 55 | D73: MINISTERIO DEL TRANSPORTE Y TELECOMUNICACIONES | E73: Medio Ambiente | F73: Establece Normas de Emisión Aplicables a Vehículos Motorizados Pesados Que Indica | G73: 1 | H73: https://www.leychile.cl/Navegar?idNorma=8364 | I73: Vigente
B74: 69 | C74: Decreto 63 | D74: MINISTERIO DEL TRABAJO Y PREVISION SOCIAL. | E74: Seguridad y Salud | F74: Aprueba reglamento para la aplicación de la Ley 20.001, que regula el peso máximo de carga humana | G74: 1 | H74: https://www.leychile.cl/Navegar?idNorma=241855 | I74: Vigente / Modificado
B75: 70 | C75: Decreto 67 | D75: MINISTERIO DEL TRABAJO Y PREVISION SOCIAL. | E75: Seguridad | F75: Aprueba Reglamento para Aplicación de Artículos 15 y 16 de Ley N°16.744, sobre exenciones, rebajas y recargos de la cotización adicional diferenciada. | G75: 1 | H75: https://www.leychile.cl/Navegar?idNorma=159800 | I75: Vigente / Modificado
B76: 71 | C76: Decreto 73 | D76: MINISTERIO DEL TRABAJO Y PREVISIÓN SOCIAL | E76: HSEC | F76: Introduce modificaciones en el reglamento para la aplicación de la ley nº16.744, que establece normas sobre accidentes del trabajo y enfermedades profesionales, contenido en el decreto supremo Nº 101, de 1968, del ministerio del trabajo y previsión social, y en el reglamento para la calificación y evaluación de los accidentes del trabajo y enfermedades profesionales, contenido en el decreto supremo Nº 109, de 1968, del ministerio del trabajo y previsión social | G76: 1 | H76: https://www.bcn.cl/leychile/navegar?idNorma=247787 | I76: Vigente
B77: 72 | C77: Decreto 76 | D77: MINISTERIO DEL TRABAJO Y PREVISION SOCIAL. | E77: Seguridad y Salud | F77: Aprueba Reglamento para la aplicación del artículo 66 bis de la Ley N° 16.744 sobre la gestión de la seguridad y salud en el trabajo en obras, faenas o servicios que indica | G77: 1 | H77: https://www.leychile.cl/Navegar?idNorma=257601 | I77: Vigente
B78: 73 | C78: Decreto 97 | D78: MINISTERIO SECRETARIA GENERAL DE LA PRESIDENCIA | E78: Seguridad y Salud | F78: Modifica Decreto N°594 de 1999, sobre condiciones básicas en los lugares de trabajo | G78: 1 | H78: https://www.bcn.cl/leychile/navegar?idNorma=1021867&idParte=9094939&idVersion=2011-03-08 | I78: Vigente
B79: 74 | C79: Decreto 100 | D79: MINISTERIO SECRETARIA GENERAL DE LA PRESIDENCIA | E79: Medio Ambiente | F79: Fija el Texto Refundido Coordinado y Sistematizado de la Constitución Política de la Republica de Chile | G79: 1 | H79: https://www.leychile.cl/Navegar?idNorma=242302 | I79: Vigente
B80: 75 | C80: Decreto 101 | D80: MINISTERIO DEL TRABAJO Y PREVISION SOCIAL. | E80: Seguridad y Salud | F80: Reglamento para la aplicación de la Ley N°16.744, que establece normas sobre Accidentes del Trabajo y Enfermedades Profesionales | G80: 1 | H80: https://www.leychile.cl/Navegar?idNorma=9231 | I80: Vigente / Modificado
B81: 76 | C81: Decreto 109 | D81: MINISTERIO DEL TRABAJO Y PREVISION SOCIAL. | E81: Seguridad y Salud | F81: Reglamento para la Calificación y Evaluación de los Accidentes del Trabajo y Enfermedades Profesionales | G81: 1 | H81: https://www.leychile.cl/Navegar?idNorma=9391 | I81: Cumplimiento O.A.L.
B82: 77 | C82: Decreto 110 | D82: MINISTERIO DEL TRABAJO Y PREVISION SOCIAL. | E82: Seguridad y Salud | F82: Escala para la determinación de la cotización adicional diferenciada | G82: 1 | H82: https://www.leychile.cl/Navegar?idNorma=179501 | I82: Vigente
B83: 78 | C83: Decreto 132 | D83: MINISTERIO DE MINERÍA | E83: Seguridad | F83: Aprueba Reglamento de Seguridad Minera | G83: 1 | H83: https://www.leychile.cl/Navegar?idNorma=221064 | I83: Vigente
B84: 79 | C84: Decreto 144 | D84: MINISTERIO DE SALUD | E84: Medio Ambiente | F84: Establece Normas Para Evitar Emanaciones o Contaminantes Atmosféricos de Cualquiera Naturaleza | G84: 1 | H84: https://www.leychile.cl/Navegar?idNorma=9981 | I84: Vigente / Modificado
... B92: 88 | C92: Decreto 1.052 Exento | D92: MINISTERIO DE SALUD | E92: Salud | F92: Aprueba Norma Técnica N°156 denominada "Protocolo sobre normas mínimas para el desarrollo de programas de vigilancia de la perdida auditiva por exposición a ruido en los lugares de trabajo" | G92: 1 | H92: https://www.leychile.cl/Navegar?idNorma=1069385 | I92: Vigente
B93: 89 | C93: Decreto 1159 Exento | D93: MINISTERIO DE SALUD | E93: Seguridad | F93: Declara normas oficiales de la Republica de Chile | G93: 1 | H93: https://www.bcn.cl/leychile/navegar?idNorma=247502&idVersion=2006-02-23
B94: 90 | C94: Resolución 19 Exenta | D94: MINISTERIO DE SALUD | E94: Seguridad | F94: Aprueba guía para la selección y control de cascos de protección uso industrial | G94: 1 | H94: https://www.leychile.cl/Navegar?idNorma=1048391 | I94: Vigente / Modificado
B95: 91 | C95: Resolución 22 Exenta | D95: MINISTERIO DE SALUD | E95: Salud | F95: Actualiza guía técnica de evaluación y control de riesgos asociados al manejo o manipulación manual de carga | G95: 1 | H95: Resolución-22 EXENTA 10-FEB-2018 MINISTERIO DEL TRABAJO Y PREVISIÓN SOCIAL - Ley Chile - Biblioteca del Congreso Nacional (bcn.cl) | I95: Vigente
B96: 92 | C96: Resolución 129 Exenta | D96: MINISTERIO DEL TRABAJO Y PREVISIÓN SOCIAL | E96: Seguridad | F96: Dicta "guía para la elaboración de mapas de riesgos laborales al interior de las entidades empleadoras" | G96: 1 | H96: Ley Chile - Resolución 129 EXENTA 18-FEB-2025 MINISTERIO DEL TRABAJO Y PREVISIÓN SOCIAL, SUBSECRETARÍA DE PREVISIÓN SOCIAL - Biblioteca del Congreso Nacional | I96: Vigente
B97: 93 | C97: Resolución 156 Exenta | D97: MINISTERIO DEL TRABAJO Y PREVISION SOCIAL. | E97: Seguridad y Salud | F97: Aprueba Compendio de Normas del Seguro Social de Accidentes del Trabajo y Enfermedades Profesionales de la Ley 16.744, Deroga y Declara Inaplicables Circulares que indica | G97: 1 | H97: https://www.leychile.cl/Navegar?idNorma=1116045 | I97: Vigente / Modificado
...

Sheet Control de Cambios
D3: CONTROL DE CAMBIOS Lista de Verificación de Cumplimiento Requisitos Legales y Otros Aplicable a Seguridad, Salud Ocupacional, Medioambiente y Comunidad Contrato 4600029025 - SKIC CC-101 | G3: Código | H3: MTRSE-00002
G4: Revisión | H4: 2
G5: Fecha | H5: 46272
C7: Código Cuerpo Legal | D7: Organismo | E7: Nombre del Cuerpo Legal | F7: Fecha modificación | G7: Revisión | H7: Comentario
C8: Ley 21.797 | D8: MINISTERIO DE TRANSPORTES Y TELECOMUNICACIONES | E8: MODIFICA LA LEY N° 18.290 Y OTROS CUERPOS LEGALES QUE INDICA, PARA HACER EFECTIVA LA EXIGENCIA DE CONTAR CON APTITUDES PARA CONDUCIR VEHÍCULOS MOTORIZADOS Y REGULAR OTRAS MATERIAS RELACIONADAS | F8: 46065 | G8: 1 | H8: Se incluye nuevos requerimeinto legal
C9: Ley 19.300 | D9: MINISTERIO SECRETARIA GENERAL DE LA PRESIDENCIA | E9: Aprueba Ley sobre bases Generales del Medio Ambiente | F9: 43229 | G9: 3 | H9: Modificado
C10: Ley 19.419 | D10: MINISTERIO DE SALUD | E10: Regula Actividades que indica Relacionadas con el Tabaco | F10: 43229 | G10: 3 | H10: Modificado
C11: Ley 19.473 | D11: MINISTERIO DE AGRICULTURA | E11: Ley de Caza y su Reglamento aprobado por D.S. Nº 5, modificado este último por D.S. Nº 53. | F11: 43229 | G11: 3 | H11: Modificado
C12: Ley 19.518 | D12: MINISTERIO DEL TRABAJO Y PREVISION SOCIAL. | E12: Fija Nuevo Estatuto de Capacitacion y Empleo | F12: 43229 | G12: 3 | H12: Modificado
C13: Ley 20.005 | D13: MINISTERIO DEL TRABAJO Y PREVISION SOCIAL. | E13: Tipifica y Sanciona el Acoso Sexual | F13: 43229 | G13: 3 | H13: Modificado
C14: Ley 20.249 | D14: MINISTERIO DE PLANIFICACION | E14: Crea el espacio costero marino de los pueblos originarios | F14: 43229 | G14: 3 | H14: Modificado
C15: Ley 20.283 | D15: MINISTERIO DE AGRICULTURA | E15: Ley sobre recuperacion del bosque nativo y fomento forestal | F15: 43229 | G15: 3 | H15: Modificado
C16: Ley 20.609 | D16: MINISTERIO SECRETARIA GENERAL DE LA PRESIDENCIA | E16: Establece medidas contra la discriminación. | F16: 43229 | G16: 3 | H16: Modificado
C17: Ley 20.660 | D17: MINISTERIO DE SALUD | E17: Modifica Ley Nº 19.419, en Materia de Ambientes Librea de Humo de Tabaco | F17: 43229 | G17: 3 | H17: El contenido de la presente Ley se encuentra incluida en Ley 19419 MINSAL
C18: Ley 20.949 | D18: MINISTERIO DEL TRABAJO Y PREVISION SOCIAL. | E18: Modifica el código del trabajo para reducir el peso de las cargas de manipulación manual | F18: 43229 | G18: 3 | H18: Modificado
C19: Decreto con Fuerza de Ley 1 | D19: MINISTERIO DEL TRANSPORTE Y TELECOMUNICACIONES | E19: Ley de Tránsito | F19: 43229 | G19: 3 | H19: Modificado
... C140: Dictamen 1161 | D140: SUPERINTENDENCIA DE SEGURIDAD SOCIAL | E140: Cobertura del seguro de la Ley 16.744, ante la contingencia provocada por el Coronavirus Covid 19, Complementa Ord. N° 1124 de 16 de marzo de 2020, de esta Superintendencia. | F140: 43966 | G140: 6 | H140: Se incorpora y Complementa Ord. N° 1124 de 16 de marzo de 2020, de esta Superintendencia.
C141: ORD. 1086 | D141: MINISTERIO DE SALUD | E141: Envía recomendaciones de Actuación en los Lugares de Trabajo en el Contexto COVID-19 | F141: 16.05.2020 | G141: 6 | H141: Se incorpora
C142: Dictamen 1013 | D142: SUPERINTENDENCIA DE SEGURIDAD SOCIAL | E142: Infección por Coronavirus Covid 19. Situaciones a considerar en la calificación de su origen. | F142: 16.05.2020 | G142: 6 | H142: Se incorpora
C143: Dictamen 1233 | D143: SUPERINTENDENCIA DE SEGURIDAD SOCIAL | E143: Constitución y funcionamiento de los Comités Paritarios de Higiene y Seguridad del sector público, ante la contingencia provocada por el Coronavirus Covid 19. | F143: 43967 | G143: 6 | H143: Se incorpora
C144: Dictamen 1239 | D144: DIRECCIÓN DEL TRABAJO | E144: Salud y Seguridad en el Trabajo | F144: 43967 | G144: 6 | H144: Se incorpora
C145: Dictamen 1389 | D145: DIRECCIÓN DEL TRABAJO | E145: Trabajo a distancia y teletrabajo | F145: 43967 | G145: 6 | H145: Se incorpora
C146: PROTOCOLO DE LIMPIEZA Y DESINFECCIÓN DE AMBIENTES - COVID-19 | D146: MINSAL | E146: PROTOCOLO DE LIMPIEZA Y DESINFECCIÓN DE AMBIENTES - COVID-19 | F146: 43967 | G146: 6 | H146: Se incorpora
C147: PROTOCOLO DE CONTACTOS DE CASOS COVID-19 FASE 4. Ver.2 | D147: MINSAL | E147: PROTOCOLO DE CONTACTOS DE CASOS COVID-19 FASE 4. Ver.2 | F147: 43967 | G147: 6 | H147: Se incorpora
C148: DECRETO 18 | D148: MINISTERIO DEL TRABAJO Y PREVISION SOCIAL. | E148: "Aprueba Reglamento del artículo 152 Quáter M del Código del Trabajo, que establece condiciones específicas de seguridad y salud en el trabajo a que deberán sujetarse los trabajadores que prestan servicios en las modalidades de trabajo a distancia o teletrabajo, de acuerdo con los principios y condiciones de la Ley Nº 16.744" | F148: 44319 | G148: 7 | H148: Se incorpora
C149: LEY 21260 | D149: DIRECCIÓN DEL TRABAJO Y PREVISIÓN SOCIAL | E149: Modifica el código del trabajo para posibilitar el teletrabajo de la trabajadora embarazada, en caso de estado de excepción constitucional de catástrofe, por calamidad pública, con ocasión de una epidemia o pandemia a causa de una enfermedad contagiosa. | F149: 44319 | G149: 7 | H149: Se incorpora
C150: Dictamen 2639 | D150: DIRECCIÓN DEL TRABAJO Y PREVISIÓN SOCIAL | E150: Elección representantes cphs y celebración reuniones utilizando medios electrónicos, mientras dure la pandemia. | F150: 44319 | G150: 7 | H150: Se incorpora
C151: FORMULARIO ÚNICO DE FISCALIZACIÓN DE MEDIDAS PREVENTIVAS PARA EL COVID-19 EN LUGARES DE TRABAJO EN LUGARES DE TRABAJO | D151: DIRECCION DEL TRABAJO Y MINISTERIO DE SALUD | E151: FORMULARIO ÚNICO DE FISCALIZACIÓN DE MEDIDAS PREVENTIVAS PARA EL COVID-19 EN LUGARES DE TRABAJO | F151: 44319 | G151: 7 | H151: Se incorpora
C152: Compendio de Normas del Seguro Social de Accidentes del Trabajo y Enfermedades Profesionales | D152: SUSESO | E152: Compendio de Normas del Seguro Social de Accidentes del Trabajo y Enfermedades Profesionales | F152: 44319 | G152: 7 | H152: Se incorpora
C153: PROGRAMA EMPRESA COMPETITIVA PEC | D153: MUTUAL DE SEGURIDAD | E153: Programa PEC | F153: 44319 | G153: 7 | H153: Se incorpora
C154: Resolución N° 2358 exenta | D154: Instituto de Salud Pública | E154: Aprueba el documento nota técnica denominada “Recomendaciones sobre prevención de COVID-19 en lugares de trabajo insertos en edificios modernos”. | F154: 44560 | G154: 8 | H154: Se incorpora
... C190: NEO 53 | D190: CODELCO - DIVISIÓN CHUQUICAMATA | E190: REGLAMENTO DE TRÁNSITO Y TRANSPORTE DE PERSONAS Y MATERIALES EN ÁREAS ADMINISTRATIVAS, PLANTAS Y SERVICIOS | F190: 46288 | G190: 2 | H190: Se individualiza en Planilla Global, se crea hoja propia y se corrige su registro en NOR.INTER.DCH. Verificar revisión controlada SGDOC.

Sheet Ley 16.744
D1: Lista de Verificación de Cumplimiento Requisitos Legales y Otros Aplicable a Seguridad, Salud Ocupacional, Medioambiente y Comunidad Contrato 4600029025 - SKIC CC-101 | M1: Código | N1: ='Planilla Global - Cumplim (%)'!I2 -> MTRSE-00002
M2: Revisión | N2: 2
M3: Fecha | N3: 46272
A5: Nº Cuerpo Legal | B5: Fecha de Publicación | C5: Organismo | D5: Nombre del Cuerpo Legal | E5: Artículo | F5: Descripción del Contenido (Breve) | G5: Peligro o Aspecto | H5: Nº Contrato | I5: Modo de Cumplimiento | J5: ¿Cumple? | K5: % Cumplimiento | L5: Evidencia del Cumplimiento | M5: Responsable | N5: Fecha de cumplimiento
A6: LEY 16.744 | B6: 24869 | C6: MINISTERIO DEL TRABAJO Y PREVISION SOCIAL | D6: ESTABLECE NORMAS SOBRE ACCIDENTES DEL TRABAJO Y ENFERMEDADES PROFESIONALES | E6: Art. 1 | F6: Declárase obligatorio el Seguro Social contra Riesgos de Accidentes del Trabajo y Enfermedades Profesionales, en la forma y condiciones establecidas en la presente ley. | G6: No estar afiliado a algún organismo Administrador Contrato del seguro | H6: 4600029025 CC-101 | I6: Afiliación a organismo Administrador ley | J6: SI | K6: 1 | L6: Certificado de afiliación Mutual de Seguridad | M6: Administrador de Contrato
E7: Art.4 | F7: Para los efectos de este seguro, todos los empleadores se entenderán afiliados al Instituto de Seguridad Laboral respecto de la totalidad de sus trabajadores, salvo que se adhieran a alguna mutualidad de empleadores. Lo dispuesto en el inciso anterior también se aplicará a los trabajadores independientes afectos al seguro de esta ley. | G7: No estar afiliado a algún organismo Administrador Contrato del seguro | I7: Pago del seguro | J7: SI | K7: 1 | L7: Planilla firmada por el OAL | M7: Administrador de Contrato
E8: Art.5 | F8: Para los efectos de esta ley se entiende por accidente del trabajo toda lesión que una persona sufra a causa o con ocasión del trabajo, y que le produzca incapacidad o muerte. Son también accidentes del trabajo los ocurridos en el trayecto directo, de ida o regreso, entre la habitación y el lugar del trabajo, y aquéllos que ocurran en el trayecto directo entre dos lugares de trabajo, aunque correspondan a distintos empleadores. En este último caso, se considerará que el accidente dice relación con el trabajo al que se dirigía el trabajador al ocurrir el siniestro. Se considerarán también accidentes del trabajo los sufridos por dirigentes de instituciones sindicales a causa o con ocasión del desempeño de sus cometidos gremiales. Exceptuándose los accidentes debidos a fuerza mayor extraña que no tenga relación alguna con el trabajo y los producidos intencionalmente por la víctima. La prueba de las excepciones corresponderá al organismo administrador. | G8: No enviar al accidentado al OAL | H8: 4600029025 CC-101 | I8: Realización de DIAT empresa | J8: SI | K8: 1 | L8: DIAT Empresa presentada en Organismo Administrador Contrato LEY o subida al sistema | M8: Administrador de Contrato
E9: Art.7 | F9: Es enfermedad profesional la causada de una manera directa por el ejercicio de la profesión o el trabajo que realice una persona y que le produzca incapacidad o muerte | G9: No realizar evaluación cualitativa con el OAL | H9: 4600029025 CC-101 | I9: Programa de Salud Ocupacional | J9: SI | K9: 1 | L9: Mantener vigente al Grupo de exposición similar | M9: Administrador de Contrato
E10: Art.15 | F10: El seguro de Accidentes del Trabajo y Enfermedades Profesionales se financiará con los siguientes recursos: a) Con una cotización básica general del 0,90% de las remuneraciones imponibles, de cargo del empleador; b) Con una cotización adicional diferenciada en función de la actividad y riesgo de la empresa o entidad empleadora, la que será determinada por el Presidente de la República y no podrá exceder de un 3,4% de las remuneraciones imponibles, que también será de cargo del empleador, y que se fijará sin perjuicio de los dispuesto en el artículo 16 c) Con el producto de las multas que cada organismo Administrador Contrato aplique en conformidad a la presente ley; d) Con las utilidades o rentas que produzca la inversión de los fondos de reserva, y e) Con las cantidades que les corresponda por el ejercicio del derecho de repetir de acuerdo con los artículos 56 y 69. | G10: No realizar pago de cotización básica | H10: 4600029025 CC-101 | I10: Pago de 0,95% de la planilla total de trabajadores + Cotización adicional | J10: SI | K10: 1 | L10: Pagos de Mutualidad | M10: Administrador de Contrato
A11: LEY 16.744 | B11: 24869 | C11: MINISTERIO DEL TRABAJO Y PREVISION SOCIAL | D11: ESTABLECE NORMAS SOBRE ACCIDENTES DEL TRABAJO Y ENFERMEDADES PROFESIONALES | E11: Art.16 | F11: Artículo 16º Las empresas o entidades que implanten o hayan implantado medidas de prevención que rebajen apreciablemente los riesgos de accidentes del trabajo o de enfermedades profesionales, podrán solicitar que se les reduzca la tasa de cotización adicional o que se les exima de ella si alcanzan un nivel óptimo de seguridad. Las empresas o entidades que no ofrezcan condiciones satisfactorias de seguridad y/o higiene, o que no implanten las medidas de seguridad que el organismo competente les ordene, deberán cancelar la cotización adicional con recargo de hasta el 100% sin perjuicio de las demás sanciones que les correspondan. | G11: No realizar actividades de Prevención de Riesgos. | H11: 4600029025 CC-101 | I11: Se cuenta con un Departamento de Prevención de Riesgos y con Programas Personalizados para la línea de Mando | J11: SI | K11: 1 | L11: Informes de Gestión HSEC | M11: Administrador de Contrato
E12: Art.66 | F12: En toda industria o faena en que trabajen más de 25 personas deberán funcionar uno o más Comités Paritarios de Higiene y Seguridad, que tendrán las siguientes funciones: 1.- Asesorar e instruir a los trabajadores para la correcta utilización de los instrumentos de protección; 2.- Vigilar el cumplimiento, tanto por parte de las empresas como de los trabajadores, de las medidas de prevención, higiene y seguridad. 3.- Investigar las causas de los accidentes del trabajo y enfermedades profesionales, que se produzcan en la empresa y de cualquiera otra afección que afecte en forma reiterada o general a los trabajadores y sea presumible que tenga su origen en la utilización de productos fitosanitarios, químicos o nocivos para la salud; 4.- Indicar la adopción de todas las medidas de higiene y seguridad, que sirvan para la prevención de los riesgos profesionales; 5.- Cumplir las demás funciones o misiones que le encomiende el organismo Administrador Contrato respectivo. | G12: No constituir Comité Paritario de Higiene y Seguridad | H12: 4600029025 CC-101 | I12: Constitución y funcionamiento de Comité Paritario | J12: SI | K12: 1 | L12: Acta de constitución de Comité Paritario Registro de reuniones mensuales C.P.H.S. Programa de Trabajo | M12: Administrador de Contrato
E13: Art.66 | F13: En aquellas empresas mineras, industriales o comerciales que ocupen a más de 100 trabajadores será obligatoria la existencia de un Departamento de Prevención de Riesgos Profesionales, el que será dirigido por un experto en prevención, en el cual formará parte. | G13: No conformar departamento de prevención de riesgos | H13: 4600029025 CC-101 | I13: Contratación profesional calificado | J13: SI | K13: 1 | L13: Contrato de trabajo del profesional | M13: Administrador de Contrato
E14: Art.66 BIS | F14: Los empleadores que contraten o subcontraten con otros la realización de una obra, faena o servicios propios de su giro, deberán vigilar el cumplimiento por parte de dichos contratistas o subcontratistas de la normativa relativa a higiene y seguridad, debiendo para ello implementar un sistema de gestión de la seguridad y salud en el trabajo para todos los trabajadores involucrados, cualquiera que sea su dependencia, cuando en su conjunto agrupen a más de 50 trabajadores. | G14: No incluir al personal subcontratista en el Programa personalizado | H14: 4600029025 CC-101 | I14: Entrega de programa personalizado | J14: N/A | K14: N/A | L14: Registro entrega de programa personalizado Registro de cumplimiento de programa | M14: Administrador de Contrato
E15: Art.67 | F15: Las empresas o entidades estarán obligadas a mantener al día los reglamentos internos de higiene y seguridad en el trabajo y los trabajadores a cumplir con las exigencias que dichos reglamentos les impongan. Los reglamentos deberán consultar la aplicación de multas a los trabajadores que no utilicen los elementos de protección personal que se les haya proporcionado o que no cumplan las obligaciones que les impongan las normas, reglamentaciones o instrucciones sobre higiene y seguridad en el trabajo. La aplicación de tales multas se regirá por lo dispuesto en el Párrafo I del Título III del Libro I del Código del Trabajo. | G15: No contar con RIOHS | H15: 4600029025 CC-101 | I15: Mantener vigente RIOHS | J15: SI | K15: 1 | L15: Cartas de presentación en DT y Seremi Salud | M15: Administrador de Contrato
A16: LEY 16.744 | B16: 24869 | C16: MINISTERIO DEL TRABAJO Y PREVISION SOCIAL | D16: ESTABLECE NORMAS SOBRE ACCIDENTES DEL TRABAJO Y ENFERMEDADES PROFESIONALES | E16: Art.68 | F16: Las empresas o entidades deberán implantar todas las medidas de higiene y seguridad en el trabajo que les prescriban directamente el Servicio Nacional de Salud o, en su caso, el respectivo organismo Administrador Contrato a que se encuentren afectas, el que deberá indicarlas de acuerdo con las normas y reglamentaciones vigentes. | G16: No cumplir con la medidas indicadas por el Servicio Nacional de Salud | H16: 4600029025 CC-101 | I16: Cierre de informe emitido por el SNS | J16: SI | K16: 1 | L16: Informe de cierre timbrado por el SNS | M16: Administrador de Contrato
E17: Art.71 | F17: Los afiliados afectados de alguna enfermedad profesional deberán ser trasladados, por la empresa donde presten sus servicios, a otras faenas donde no estén expuestos al agente causante de la enfermedad. Los trabajadores que sean citados para exámenes de control por los servicios médicos de los organismos administradores, deberán ser autorizados por su empleador para su asistencia, y el tiempo que en ello utilicen será considerado como trabajado para todos los efectos legales. Las empresas que exploten faenas en que trabajadores suyos puedan estar expuestos al riesgo de neumoconiosis, deberán realizar un control radiográfico semestral de tales trabajadores. | G17: No implantar las medidas de higiene y seguridad que prescriba el organismo administrador No proporcionar gratuitamente los Equipos de Protección Personal adecuados a los trabajadores | H17: 4600029025 CC-101 | I17: Informe de mutualidad respecto a las medidas a implantar Entrega de Equipos de protección personal en forma gratuita a trabajadores | J17: SI | K17: 1 | L17: Cuando corresponda Registro de entrega de Equipos de Protección Personal a trabajadores | M17: Administrador de Contrato
E18: Art.76 | F18: La entidad empleadora deberá denunciar al organismo Administrador Contrato respectivo, inmediatamente de producido, todo accidente o enfermedad que pueda ocasionar incapacidad para el trabajo o la muerte de la víctima. El accidentado o enfermo, o sus derecho-habientes, o el médico que trató o diagnosticó la lesión o enfermedad, como igualmente el Comité Paritario de Seguridad, tendrán también, la obligación de denunciar el hecho en dicho organismo administrador, en el caso de que la entidad empleadora no hubiere realizado la denuncia. Las denuncias mencionadas en el inciso anterior deberán contener todos los datos que hayan sido indicados por el Servicio Nacional de Salud. | G18: No controlar los peligros adecuadamente | H18: 4600029025 CC-101 | I18: Responsabilidad establecida en Investigación de Incidentes | J18: SI | K18: 1 | L18: Registros de Investigación de Incidentes (Cuando Corresponda) | M18: Administrador de Contrato
K19: 1
C20: ELABORÓ | F20: REVISÓ | G20: APROBÓ
C21: Claudio Rojas / Jefe Dpto. HSEC | F21: Mauricio Araya / Presidente CPHS | G21: José Maira / Administrador de Contrato
C22: FIRMA: FECHA : 18-02-2026 | F22: FIRMA: FECHA : 18-02-2026 | G22: FIRMA: FECHA : 18-02-2026

Sheet Ley 18.290
D1: Lista de Verificación de Cumplimiento Requisitos Legales y Otros Aplicable a Seguridad, Salud Ocupacional, Medioambiente y Comunidad Contrato 4600029025 - SKIC CC-101 | M1: Código | N1: ='Planilla Global - Cumplim (%)'!I2 -> MTRSE-00002
M2: Revisión | N2: 2
M3: Fecha | N3: 46272
A5: Nº Cuerpo Legal | B5: Fecha de Publicación | C5: Organismo | D5: Nombre del Cuerpo Legal | E5: Artículo | F5: Descripción del Contenido (Breve) | G5: Peligro o Aspecto | H5: Nº Contrato | I5: Modo de Cumplimiento | J5: ¿Cumple? | K5: Porcentaje Cumplimiento | L5: Evidencia del Cumplimiento | M5: Responsable | N5: Fecha de cumplimiento
A6: Ley 18.290 | B6: 30719 | C6: MINISTERIO DE JUSTICIA | D6: LEY DEL TRANSITO | E6: Art.5 | F6: Ninguna persona podrá conducir un vehículo motorizado o a tracción animal, sin poseer una licencia expedida por el Director del Departamento del Tránsito y Transporte Público Municipal de una Municipalidad autorizada al efecto; o un permiso provisional que los Tribunales podrán otorgar sólo a los conductores que tengan su licencia retenida por proceso pendiente; o una boleta de citación al Juzgado, dada por los funcionarios a que se refiere el artículo 4º en reemplazo de la licencia o del permiso referido; o algún documento extendido en el extranjero y con validez en Chile en virtud de tratados o acuerdos internacionales. Los documentos antes indicados otorgados en el país, son instrumentos públicos. Se exceptúa de la exigencia establecida en el inciso primero de este artículo a los alumnos en práctica de las escuelas de conductores que, acompañados de un instructor habilitado, lo hagan en vehículos de la escuela. | G6: Conducir, operar vehículos y/o maquinarias sin autorización por organismo competente | H6: 4600029025 CC-101 | I6: Listado actualizado de Conductores | J6: SI | K6: 1 | L6: Registro de conductores que indique tipo licencia y fecha de vencimientos | M6: Jefe Equipos/ Base Deysu
E7: Art.6 | F7: Los conductores de vehículos motorizados o a tracción animal, salvo la excepción del artículo anterior, deberán llevar consigo su licencia, permiso o boleta de citación y, requeridos por la autoridad competente, acreditar su identidad y entregar los documentos que los habilitan para conducir. Asimismo, tratándose de vehículos motorizados, deberán portar y entregar el certificado vigente de póliza de un seguro obligatorio de accidentes, el que deberá ser devuelto, siempre y en el acto, al conductor. | G7: Conducir, operar vehículos y/o maquinarias sin el documento que acredite la autorización mas documentación del vehículo o maquinaria. | H7: 4600029025 CC-101 | I7: Listado actualizado de Conductores | J7: SI | K7: 1 | L7: carpeta de documentación del vehículo con todos los documentos vigentes | M7: Jefe Equipos/ Base Deysu
E8: Art.7 | F8: Se prohíbe al propietario o encargado de un vehículo facilitarlo a una persona que no posea licencia para conducirlo. Si se sorprendiere conduciendo un vehículo a quien no porte los documentos a que se refiere el artículo anterior. | G8: Conducir, operar vehículos y/o maquinarias sin el documento que acredite la autorización | H8: 4600029025 CC-101 | I8: Listado de personas autorizadas | J8: SI | K8: 1 | L8: carta compromiso conducir firmada | M8: Jefe Equipos/ Base Deysu
A9: Ley 18.290 | B9: 30719 | C9: MINISTERIO DE JUSTICIA | D9: LEY DEL TRANSITO | E9: Art.12 | F9: Existirán licencias de conductor profesionales, Clase A; no profesionales, Clase B y C; y especiales, Clase D, E y F. | G9: Conducir, operar vehículos y/o maquinarias sin el documento que acredite la autorización | H9: 4600029025 CC-101 | I9: Listado de personas autorizadas | J9: SI | K9: 1 | L9: carta compromiso conducir firmada | M9: Jefe Equipos/ Base Deysu
E10: Art.60 | F10: No se podrá transportar materias peligrosas en vehículos de alquiler ni en los destinados al transporte colectivo de personas | G10: Transportar sustancias peligrosas en vehículos de transporte de personas | H10: 4600029025 CC-101 | I10: Charla ODI medioambiente | J10: SI | K10: 1 | L10: Charla ODI medioambiente firmada | M10: Jefe Equipos/ Base Deysu
E11: Art.63 | F11: Los vehículos motorizados deberán estar equipados con neumáticos en buen estado. No podrán circular aquellos cuyos neumáticos tengan sus bandas de rodadura desgastadas o hayan perdido sus condiciones de adherencia al pavimento, ni con repara | G11: Circular en vehículo con neumáticos desgastados o en malas condiciones | H11: 4600029025 CC-101 | I11: Lista de chequeo diario de vehículos | J11: SI | K11: 1 | L11: Registro de listas de chequeo | M11: Jefe Equipos/ Base Deysu
E12: Art.101 | F12: Los conductores y los peatones están obligados a obedecer y respetar las señales del tránsito, salvo que reciban instrucciones en contrario de un carabinero o que se trate de las excepciones contempladas en esta ley para vehículos de emerge | G12: No respetar señalización de transito | H12: 4600029025 CC-101 | I12: Realización de Curso de manejo defensivo a conductores online o presencial | J12: SI | K12: 1 | L12: Certificado aprobación curso manejo defensivo | M12: Jefe Equipos/ Base Deysu
E13: Art.148 | F13: Ninguna persona podrá conducir un vehículo a una velocidad mayor de la que sea razonable y prudente, bajo las condiciones existentes, debiendo considerar los riesgos y peligros presentes y los posibles. | G13: Conducir vehículo a velocidad inadecuada | H13: 4600029025 CC-101 | I13: Control GPS | J13: SI | K13: 1 | L13: Reporte semanal GPS | M13: Jefe Equipos/ Base Deysu
K14: 1
C15: ELABORÓ | F15: REVISÓ | G15: APROBÓ
C16: Claudio Rojas / Jefe Dpto. HSEC | F16: Mauricio Araya / Presidente CPHS | G16: José Maira / Administrador de Contrato
C17: FIRMA: FECHA : 18-02-2026 | F17: FIRMA: FECHA : 18-02-2026 | G17: FIRMA: FECHA : 18-02-2026

Sheet Ley 19.303
D1: Lista de Verificación de Cumplimiento Requisitos Legales y Otros Aplicable a Seguridad, Salud Ocupacional, Medioambiente y Comunidad Contrato 4600029025 - SKIC CC-101 | M1: Código | N1: ='Planilla Global - Cumplim (%)'!I2 -> MTRSE-00002
M2: Revisión | N2: 2
M3: Fecha | N3: 46272
A5: Nº Cuerpo Legal | B5: Fecha de Publicación | C5: Organismo | D5: Nombre del Cuerpo Legal | E5: Artículo | F5: Descripción del Contenido (Breve) | G5: Peligro o Aspecto | H5: Nº Contrato | I5: Modo de Cumplimiento | J5: ¿Cumple? | K5: Porcentaje Cumplimiento | L5: Evidencia del Cumplimiento | M5: Responsable | N5: Fecha de cumplimiento
A6: Ley 19303 | B6: 34437 | C6: MINISTERIO DEL INTERIOR | D6: ESTABLECE OBLIGACIONES A ENTIDADES QUE INDICA, EN MATERIA DE SEGURIDAD DE LAS PERSONAS | E6: Art. 14 | F6: Los daños físicos o síquicos que sufran los trabajadores de las empresas, entidades o establecimientos que sean objeto de robo, asalto u otra forma de violencia delictual, a causa o con ocasión del trabajo, son accidentes del trabajo, sujetos a las normas de la ley N° 16.744. | G6: ROBO/ASALTO | H6: 4600029025 CC-101 | I6: Emisión de DIAT | J6: SI | K6: 1 | L6: DIAT timbrada o subida al sistema del OAL | M6: Administrador de Contrato
K7: 1
C8: ELABORÓ | F8: REVISÓ | G8: APROBÓ
C9: Claudio Rojas / Jefe Dpto. HSEC | F9: Mauricio Araya / Presidente CPHS | G9: José Maira / Administrador de Contrato
C10: FIRMA: FECHA : 18-02-2026 | F10: FIRMA: FECHA : 18-02-2026 | G10: FIRMA: FECHA : 18-02-2026

Sheet LEY 19.404
D1: Lista de Verificación de Cumplimiento Requisitos Legales y Otros Aplicable a Seguridad, Salud Ocupacional, Medioambiente y Comunidad Contrato 4600029025 - SKIC CC-101 | M1: Código | N1: ='Planilla Global - Cumplim (%)'!I2 -> MTRSE-00002
M2: Revisión | N2: 2
M3: Fecha | N3: 46272
A5: Nº Cuerpo Legal | B5: Fecha de Publicación | C5: Organismo | D5: Nombre del Cuerpo Legal | E5: Artículo | F5: Descripción del Contenido (Breve) | G5: Peligro o Aspecto | H5: Nº Contrato | I5: Modo de Cumplimiento | J5: ¿Cumple? | K5: Porcentaje Cumplimiento | L5: Evidencia del Cumplimiento | M5: Responsable | N5: Fecha de cumplimiento
A6: Ley 19.404 | B6: 34932 | C6: MINISTERIO DE SALUD | D6: Introduce modificación al Decreto Ley Nº 3.500, de 1980, Texto Original del 01-03-2009 y dicta normas relativas a pensiones de vejez, considerando el desempeño de trabajos pesados. | E6: Art.1 | F6: Se entenderá que constituyen trabajos pesados aquellos cuya realización acelera el desgaste físico, intelectual o psíquico en la mayoría de quienes lo realizan, provocando un envejecimiento precoz, aun cuando ellos no generen una enfermedad laboral. | G6: No identificar los puestos de trabajo | H6: 4600029025 CC-101 | I6: Realizar Evaluación del puesto de trabajo por la comisión Ergonómica | J6: NO | K6: 0 | L6: Informe ergonómico OAL y presentar a la SEREMI de la región que corresponda Enviar informe a RRHH | M6: Administrador de contrato RRLL | P6: https://www.bcn.cl/leychile/navegar?idNorma=30771
E7: Art.2 | F7: Para los efectos de calificar como trabajo pesado una labor, que se ejecuta en uno o más puestos de trabajo de una determinada entidad empleadora, las Comisiones a que se refiere el presente Reglamento, deberán establecer un instrumento guía de conocimiento público, uso obligatorio y revisión permanente, considerando a lo menos, y con independencia de las características individuales de quien la realiza, los siguientes factores: a) Factor físico: constituido por las exigencias del puesto de trabajo que demandan un esfuerzo adaptativo fisiológico, reflejado en mayor gasto energético y con modificaciones del metabolismo. b) Factor ambiental: que corresponde a la presencia, en los puestos de trabajo, de agentes ambientales que pueden afectar negativamente la salud de los trabajadores, su bienestar y su equilibrio fisiológico. c) Factor mental: es la exigencia del puesto de trabajo que demanda esfuerzos adaptativos del sistema nervioso y de la estructura psicoafectiva del trabajador. d) Factor organizacional: son las exigencias del puesto de trabajo derivadas de la organización y diseño de la labor y su entorno psicosocial. Para los efectos de lo dispuesto en la Ley Nº 19.404 y en el presente Reglamento, se entiende por puesto de trabajo el conjunto de tareas, deberes y responsabilidades que, en el marco de las condiciones de trabajo definidas por la empresa, constituyen la labor regular de una persona y que pueden ser descritas con prescindencia del trabajador que lo ocupa. | G7: No identificar los puestos de trabajo | H7: 4600029025 CC-101 | I7: Realizar Evaluación del puesto de trabajo por la comisión Ergonómica | J7: NO | K7: 0 | L7: Informe ergonómico OAL y presentar a la SEREMI de la región que corresponda Enviar informe a RRHH | M7: Administrador de contrato
E8: Art.3 | F8: La definición de trabajo pesado y los factores de carga global de trabajo señalados en los artículos anteriores, serán aplicados y ponderados, en su totalidad, por la Comisión Ergonómica Nacional para la calificación por puesto de trabajo de las labores desarrolladas por los afiliados al Sistema de Pensiones del D. L. Nº 3.500, de 1980, y por los imponentes de los regímenes previsionales administrados por el Instituto de Normalización Previsional a que se refieren los artículos 1º y 2º de la Ley Nº 19.404.6 7 El menor desgaste relativo producido por un trabajo calificado como pesado, será determinado según la ponderación asignada a cada uno de los factores señalados en el artículo anterior, conforme lo establecido en el instrumento guía a que se refiere el artículo 2º de este Reglamento. | G8: No identificar los puestos de trabajo | H8: 4600029025 CC-101 | I8: Realizar Evaluación del puesto de trabajo por la comisión Ergonómica | J8: NO | K8: 0 | L8: Informe ergonómico OAL y presentar a la SEREMI de la región que corresponda Enviar informe a RRHH | M8: Administrador de contrato
K9: 0
C10: ELABORÓ | F10: REVISÓ | G10: APROBÓ
C11: Claudio Rojas / Jefe Dpto. HSEC | F11: Mauricio Araya / Presidente CPHS | G11: José Maira / Administrador de Contrato
C12: FIRMA: FECHA : 18-02-2026 | F12: FIRMA: FECHA : 18-02-2026 | G12: FIRMA: FECHA : 18-02-2026

Sheet Ley 19.419
D1: Lista de Verificación de Cumplimiento Requisitos Legales y Otros Aplicable a Seguridad, Salud Ocupacional, Medioambiente y Comunidad Contrato 4600029025 - SKIC CC-101 | M1: Código | N1: ='Planilla Global - Cumplim (%)'!I2 -> MTRSE-00002
M2: Revisión | N2: 2
M3: Fecha | N3: 46272
A5: Nº Cuerpo Legal | B5: Fecha de Publicación | C5: Organismo | D5: Nombre del Cuerpo Legal | E5: Artículo | F5: Descripción del Contenido (Breve) | G5: Peligro o Aspecto | H5: Nº Contrato | I5: Modo de Cumplimiento | J5: ¿Cumple? | K5: Porcentaje Cumplimiento | L5: Evidencia del Cumplimiento | M5: Responsable | N5: Fecha de cumplimiento
A6: Ley 19.419 | B6: 34981 | C6: MINISTERIO DE SALUD | D6: Regula Actividades que indica Relacionadas con el Tabaco | E6: Art.11 | F6: Se prohíbe fumar en los siguientes lugares, salvo en sus patios o espacios al aire libre: a) al interior de los recintos o dependencias de los órganos del Estado. Sin embargo, en las oficinas individuales se podrá fumar sólo en el caso que cuenten con ventilación hacia el aire libre o extracción del aire hacia el exterior; b) establecimientos de educación superior, públicos y privados; c) establecimientos de salud, públicos y privados; d) aeropuertos y terrapuertos; e) teatros, cines, lugares en que se presenten espectáculos culturales y musicales, salvo que sean al aire libre; f) gimnasios y recintos deportivos; g) centros de atención o de prestación de servicios abiertos al público en general; h) supermercados, centros comerciales y demás establecimientos similares de libre acceso al público. En los lugares anteriormente enumerados, podrá existir una o más salas especialmente habilitadas para fumar, con excepción de los casos que señala la letra c). Sin perjuicio de lo dispuesto en el artículo siguiente, iguales reglas se aplicarán tratándose de empresas, establecimientos, faenas o unidades económicas obligadas a confeccionar un reglamento interno de orden, higiene y seguridad, en conformidad a las normas del Código del Trabajo. En los lugares de trabajo de propiedad de particulares no comprendidos en el artículo 10 y en los incisos precedentes, la existencia de prohibición de fumar o la determinación de sitios y condiciones en que ello se autorizará serán acordadas por los respectivos propietarios o administradores, oyendo el parecer de los empleados. | G6: Contaminación del Ambiente / Incendios | H6: 4600029025 CC-101 | I6: Prohibición de fumar en Áreas de Trabajo indicado en el RIOHS | J6: SI | K6: 1 | L6: registro de entrega de RIOHS, Definición de Zonas para Fumadores. | M6: Administrador de Contrato - HSEC
K7: 1
C8: ELABORÓ | F8: REVISÓ | G8: APROBÓ
C9: Claudio Rojas / Jefe Dpto. HSEC | F9: Mauricio Araya / Presidente CPHS | G9: José Maira / Administrador de Contrato
C10: FIRMA: FECHA : 18-02-2026 | F10: FIRMA: FECHA : 18-02-2026 | G10: FIRMA: FECHA : 18-02-2026

Sheet LEY 19.518
D1: Lista de Verificación de Cumplimiento Requisitos Legales y Otros Aplicable a Seguridad, Salud Ocupacional, Medioambiente y Comunidad Contrato 4600029025 - SKIC CC-101 | M1: Código | N1: ='Planilla Global - Cumplim (%)'!I2 -> MTRSE-00002
M2: Revisión | N2: 2
M3: Fecha | N3: 46272
A5: Nº Cuerpo Legal | B5: Fecha de Publicación | C5: Organismo | D5: Nombre del Cuerpo Legal | E5: Artículo | F5: Descripción del Contenido (Breve) | G5: Peligro o Aspecto | H5: Nº Contrato | I5: Modo de Cumplimiento | J5: ¿Cumple? | K5: Porcentaje Cumplimiento | L5: Evidencia del Cumplimiento | M5: Responsable | N5: Fecha de cumplimiento
A6: Ley 19.518 | B6: 35717 | C6: MINISTERIO DEL TRABAJO Y PREVISIÓN | D6: FIJA NUEVO ESTATUTO DE CAPACITACION Y EMPLEO | E6: Art.13 | F6: Las empresas podrán constituir un comité bipartito de capacitación. Ello será obligatorio en aquellas empresas cuya dotación de personal sea igual o superior a 15 trabajadores. Las funciones del comité serán acordar y evaluar el o los programas de capacitación ocupacional de la empresa, así como asesorar a la dirección de la misma en materias de capacitación. | G6: No contar con Comité Bipartito | H6: 4600029025 CC-101 | I6: Conformar Comité Bipartito | J6: NO | K6: 0 | L6: Acta de conformación de comité Bipartito | M6: Administrador de Contrato- RRHH | N6: 46142 | P6: https://www.bcn.cl/leychile/navegar?idNorma=76201
E7: Art. 14 | F7: Los programas acordados con el comité bipartito de la empresa, darán derecho a las empresas a acceder al beneficio adicional establecido en el artículo 39 de esta ley. | G7: No contar con Comité Bipartito | H7: 4600029025 CC-101 | I7: Conformar Comité Bipartito | J7: NO | K7: 0 | L7: Programa de Capacitación | M7: Administrador de Contrato- RRHH | N7: 46142
E8: Art.15 | F8: El programa de capacitación contendrá a lo menos las siguientes menciones: a) las áreas de la empresa para las cuales se desarrollarán actividades de capacitación, y el objetivo de dichas actividades; b) el número y características de los trabajadores que participarán en las actividades de capacitación, y c) la época del año en que se ejecutarán las referidas acciones. | G8: No contar con Comité Bipartito | H8: 4600029025 CC-101 | I8: Conformar Comité Bipartito | J8: NO | K8: 0 | L8: Programa de Capacitación | M8: Administrador de Contrato- RRHH | N8: 46142
E9: Art.16 | F9: El comité bipartito estará constituido por tres representantes del empleador y tres de los trabajadores. El comité se reunirá a requerimiento de a lo menos cuatro de sus integrantes. El comité adoptará sus decisiones con el acuerdo de la mayoría de los representantes de ambos estamentos, y se formalizarán para los efectos del artículo 14 de esta ley en un programa de capacitación. | G9: No contar con Comité Bipartito | H9: 4600029025 CC-101 | I9: Conformar Comité Bipartito | J9: NO | K9: 0 | L9: Acta de conformación de comité Bipartito | M9: Administrador de Contrato- RRHH | N9: 46142
K10: 0
C11: ELABORÓ | F11: REVISÓ | G11: APROBÓ
C12: Claudio Rojas / Jefe Dpto. HSEC | F12: Mauricio Araya / Presidente CPHS | G12: José Maira / Administrador de Contrato
C13: FIRMA: FECHA : 18-02-2026 | F13: FIRMA: FECHA : 18-02-2026 | G13: FIRMA: FECHA : 18-02-2026

Sheet Ley 19.628
D1: Lista de Verificación de Cumplimiento Requisitos Legales y Otros Aplicable a Seguridad, Salud Ocupacional, Medioambiente y Comunidad Contrato 4600029025 - SKIC CC-101 | M1: Código | N1: ='Planilla Global - Cumplim (%)'!I2 -> MTRSE-00002
M2: Revisión | N2: 2
M3: Fecha | N3: 46272
A5: Nº Cuerpo Legal | B5: Fecha de Publicación | C5: Organismo | D5: Nombre del Cuerpo Legal | E5: Artículo | F5: Descripción del Contenido (Breve) | G5: Peligro o Aspecto | H5: Nº Contrato | I5: Modo de Cumplimiento | J5: ¿Cumple? | K5: Porcentaje Cumplimiento | L5: Evidencia del Cumplimiento | M5: Responsable | N5: Fecha de cumplimiento
A6: Ley 19.628 | B6: 36400 | C6: MINISTERIO SECRETARÍA GENERAL DE LA PRESIDENCIA | D6: SOBRE PROTECCION DE LA VIDA PRIVADA | E6: Art.4 | F6: El tratamiento de los datos personales sólo puede efectuarse cuando esta ley u otras disposiciones legales lo autoricen o el titular consienta expresamente en ello. La persona que autoriza debe ser debidamente informada respecto del propósito del almacenamiento de sus datos personales y su posible comunicación al público. La autorización debe constar por escrito. La autorización puede ser revocada, aunque sin efecto retroactivo, lo que también deberá hacerse por escrito. No requiere autorización el tratamiento de datos personales que provengan o que se recolecten de fuentes accesibles al público, cuando sean de carácter económico, financiero, bancario o comercial, se contengan en listados relativos a una categoría de personas que se limiten a indicar antecedentes tales como la pertenencia del individuo a ese grupo, su profesión o actividad, sus títulos educativos, dirección o fecha de nacimiento, o sean necesarios para comunicaciones comerciales de respuesta directa o comercialización o venta directa de bienes o servicios. Tampoco requerirá de esta autorización el tratamiento de datos personales que realicen personas jurídicas privadas para el uso exclusivo suyo, de sus asociados y de las entidades a que están afiliadas, con fines estadísticos, de tarificación u otros de beneficio general de aquéllos. | G6: Mal manejo de información | H6: 4600029025 CC-101 | I6: Incorporado en RIOHS/ Ficha Personal | J6: SI | K6: 1 | L6: Incorporado en RIOHS/Ficha Personal | M6: Administrador de Contrato - RRLL
E7: Art.6 | F7: Los datos personales deberán ser eliminados o cancelados cuando su almacenamiento carezca de fundamento legal o cuando hayan caducado. Han de ser modificados cuando sean erróneos, inexactos, equívocos o incompletos. Se bloquearán los datos personales cuya exactitud no pueda ser establecida o cuya vigencia sea dudosa y respecto de los cuales no corresponda la cancelación. El responsable del banco de datos personales procederá a la eliminación, modificación o bloqueo de los datos, en su caso, sin necesidad de requerimiento del titular. | G7: Mal manejo de información | H7: 4600029025 CC-101 | I7: Tratamiento de documentos obsoletos | J7: SI | K7: 1 | L7: Tratamiento de documentos obsoletos | M7: Administrador de Contrato
E8: Art.7 | F8: Las personas que trabajan en el tratamiento de datos personales, tanto en organismos públicos como privados, están obligadas a guardar secreto sobre los mismos, cuando provengan o hayan sido recolectados de fuentes no accesibles al público, como asimismo sobre los demás datos y antecedentes relacionados con el banco de datos, obligación que no cesa por haber terminado sus actividades en ese campo. | G8: Mal manejo de información | H8: 4600029025 CC-101 | I8: Personal exclusivo de manejo de información | J8: SI | K8: 1 | L8: Personal exclusivo de manejo de información | M8: Administrador de Contrato
E9: Art.9 | F9: Los datos personales deben utilizarse sólo para los fines para los cuales hubieren sido recolectados, salvo que provengan o se hayan recolectado de fuentes accesibles al público. | G9: Mal manejo de información | H9: 4600029025 CC-101 | I9: Uso en carpetas Personales | J9: SI | K9: 1 | L9: Uso en carpetas Personales | M9: Administrador de Contrato
E10: Art.11 | F10: El responsable de los registros o bases donde se almacenen datos personales con posterioridad a su recolección deberá cuidar de ellos con la debida diligencia, haciéndose responsable de los daños. | G10: Mal manejo de información | H10: 4600029025 CC-101 | I10: Uso en carpetas Personales | J10: SI | K10: 1 | L10: Uso en carpetas Personales | M10: Administrador de Contrato
E11: Art.24 | F11: Agregase los siguientes incisos segundo y tercero, nuevos, al artículo 127 del Código Sanitario: ''Las recetas médicas y análisis o exámenes de laboratorios clínicos y servicios relacionados con la salud son reservados. Sólo podrá revelarse su contenido o darse copia de ellos con el consentimiento expreso del paciente, otorgado por escrito | G11: Mal manejo de información | H11: 4600029025 CC-101 | I11: Examen Preocupacional / Ocupacional o Especifico | J11: SI | K11: 1 | L11: Registro de Consentimiento en Organismo Administrador | M11: Administrador de Contrato
K12: 1
C13: ELABORÓ | F13: REVISÓ | G13: APROBÓ
C14: Claudio Rojas / Jefe Dpto. HSEC | F14: Mauricio Araya / Presidente CPHS | G14: José Maira / Administrador de Contrato
C15: FIRMA: FECHA : 18-02-2026 | F15: FIRMA: FECHA : 18-02-2026 | G15: FIRMA: FECHA : 18-02-2026

Sheet Ley 19.728
D1: Lista de Verificación de Cumplimiento Requisitos Legales y Otros Aplicable a Seguridad, Salud Ocupacional, Medioambiente y Comunidad Contrato 4600029025 - SKIC CC-101 | M1: Código | N1: ='Planilla Global - Cumplim (%)'!I2 -> MTRSE-00002
M2: Revisión | N2: 2
M3: Fecha | N3: 46272
A5: Nº Cuerpo Legal | B5: Fecha de Publicación | C5: Organismo | D5: Nombre del Cuerpo Legal | E5: Articulo | F5: Descripción del Contenido (Breve) | G5: Peligro o Aspecto | H5: Nº Contrato | I5: Modo de Cumplimiento | J5: ¿Cumple? | K5: Porcentaje Cumplimiento | L5: Evidencia del Cumplimiento | M5: Responsable | N5: Fecha de cumplimiento
A6: Ley 19728 | B6: 37025 | C6: MINISTERIO DEL TRABAJO Y PREVISIÓN SOCIAL; SUBSECRETARÍA DEL TRABAJO | D6: ESTABLECE UN SEGURO DE DESEMPLEO | E6: Art.1 | F6: Establece un seguro obligatorio de cesantía, en adelante "el Seguro", en favor de los trabajadores dependientes regidos por el Código del Trabajo, en las condiciones previstas en la presente ley. El Seguro será administrado por una sociedad anónima denominada Sociedad Administradora de Fondos de Cesantía, en adelante Sociedad Administradora, que se regulará conforme a las disposiciones de la presente ley. | G6: Incumplimiento Legal | H6: 4600029025 CC-101 | I6: Información en liquidación de sueldos (AFC) | J6: SI | K6: 1 | L6: Liquidación de Sueldo firmada y/o enviada por correo | M6: Administrador de Contrato
E7: Art.2 | F7: Estarán sujetos al Seguro los trabajadores dependientes que inicien o reinicien actividades laborales con posterioridad a la entrada en vigencia de la presente ley.
K8: 1
C9: ELABORÓ | F9: REVISÓ | G9: APROBÓ
C10: Claudio Rojas / Jefe Dpto. HSEC | F10: Mauricio Araya / Presidente CPHS | G10: José Maira / Administrador de Contrato
C11: FIRMA: FECHA : 18-02-2026 | F11: FIRMA: FECHA : 18-02-2026 | G11: FIRMA: FECHA : 18-02-2026

Sheet LEY 20.000
D1: Lista de Verificación de Cumplimiento Requisitos Legales y Otros Aplicable a Seguridad, Salud Ocupacional, Medioambiente y Comunidad Contrato 4600029025 - SKIC CC-101 | M1: Código | N1: ='Planilla Global - Cumplim (%)'!I2 -> MTRSE-00002
M2: Revisión | N2: 2
M3: Fecha | N3: 46272
A5: Nº Cuerpo Legal | B5: Fecha de Publicación | C5: Organismo | D5: Nombre del Cuerpo Legal | E5: Artículo | F5: Descripción del Contenido (Breve) | G5: Peligro o Aspecto | H5: Nº Contrato | I5: Modo de Cumplimiento | J5: ¿Cumple? | K5: Porcentaje Cumplimiento | L5: Evidencia del Cumplimiento | M5: Responsable | N5: Fecha de cumplimiento
A6: Ley 20.000 | B6: 38399 | C6: Ministerio del Interior | D6: SUSTITUYE LA LEY Nº 19.366, QUE SANCIONA EL TRAFICO ILICITO DE ESTUPEFACIENTES Y SUSTANCIAS SICOTROPICAS | E6: Art.1 | F6: Los que elaboren, fabriquen, transformen, preparen o extraigan sustancias o drogas estupefacientes o sicotrópicas productoras de dependencia física o síquica, capaces de provocar graves efectos tóxicos o daños considerables a la salud, sin la debida autorización, serán castigados con presidio mayor en sus grados mínimo a medio y multa de cuarenta a cuatrocientas unidades tributarias mensuales. | G6: Drogas y Alcohol | H6: 4600029025 CC-101 | I6: RIOHS / POLITICA ALCOHOL Y DROGRAS | J6: SI | K6: 1 | L6: Entrega RIOHS - Difusión política alcohol y drogas | M6: RRHH | P6: https://www.bcn.cl/leychile/navegar?idNorma=235507
E7: Art.2 | F7: La producción, fabricación, elaboración, distribución, transporte, comercialización, importación, exportación, posesión o tenencia de precursores o de sustancias químicas esenciales, con el objetivo de destinarlos a la preparación de drogas estupefacientes o sustancias sicotrópicas para perpetrar, dentro o fuera del país, alguno de los hechos considerados como delitos en esta ley, será castigado con presidio menor en su grado máximo a presidio mayor en su grado mínimo y multa de cuarenta a cuatrocientas unidades tributarias mensuales. | G7: Drogas y Alcohol | H7: 4600029025 CC-101 | I7: RIOHS / POLITICA ALCOHOL Y DROGRAS | J7: SI | K7: 1 | L7: Acta de conformación de comité Bipartito | M7: RRHH
E8: Art.3 | F8: Las penas establecidas en el artículo 1º se aplicarán también a quienes trafiquen, bajo cualquier título, con las sustancias a que dicha disposición se refiere, o con las materias primas que sirvan para obtenerlas y a quienes, por cualquier medio, induzcan, promuevan o faciliten el uso o consumo de tales sustancias. Se entenderá que trafican los que, sin contar con la autorización competente, importen, exporten, transporten, adquieran, transfieran, sustraigan, posean, suministren, guarden o porten tales sustancias o materias primas. | G8: Drogas y Alcohol | H8: 4600029025 CC-101 | I8: RIOHS / POLITICA ALCOHOL Y DROGRAS | J8: SI | K8: 1 | L8: Programa de Capacitación | M8: RRHH
E9: Art.4 | F9: El que, sin la competente autorización posea, transporte, guarde o porte consigo pequeñas cantidades de sustancias o drogas estupefacientes o sicotrópicas, productoras de dependencia física o síquica, o de materias primas que sirvan para obtenerlas, sea que se trate de las indicadas en los incisos primero o segundo del artículo 1º, será castigado con presidio menor en sus grados medio a máximo y multa de diez a cuarenta unidades tributarias mensuales, a menos que justifique que están destinadas a la atención de un tratamiento médico o a su uso o consumo personal exclusivo y próximo en el tiempo. En igual pena incurrirá el que adquiera, transfiera, suministre o facilite a cualquier título pequeñas cantidades de estas sustancias, drogas o materias primas, con el objetivo de que sean consumidas o usadas por otro. Se entenderá que no concurre la circunstancia de uso o consumo personal exclusivo y próximo en el tiempo, cuando la calidad o pureza de la droga poseída, transportada, guardada o portada no permita racionalmente suponer que está destinada al uso o consumo descrito o cuando las circunstancias de la posesión, transporte, guarda o porte sean indiciarias del propósito de traficar a cualquier título. | G9: Drogas y Alcohol | H9: 4600029025 CC-101 | I9: RIOHS / POLITICA ALCOHOL Y DROGRAS | J9: SI | K9: 1 | L9: Programa de Capacitación | M9: RRHH
